Workbook

Sheet Read Me
B1: THE SOBER STRENGTH SYSTEM
B2: Editable tracker — companion to the 12-week program PDF
B5: HOW TO USE THIS FILE
B6: 1. Open the 'Daily Check-In' tab and type your start date in cell B4. Everything else dates itself from there.
B7: 2. Each morning, fill in the Sleep and Craving columns from the dropdowns. The Status column turns itself
B8: Green, Amber or Red and tells you which version of the session to run.
B9: 3. After training, add your sets to the 'Training Log' tab. Estimated 1RM calculates automatically.
B10: 4. The 'Dashboard' tab totals everything. You never type anything into it.
B12: WHICH CELLS YOU TYPE IN
B13: White cells with a border are for you. Grey cells are calculated — if you type over one you will break
B14: its formula. If that happens, close the file without saving and reopen it.
B16: OPENS IN
... B28: exercise program or changing alcohol consumption. Personal use only — not for resale or redistribution.

Sheet Lists
A1: Good | B1: Quiet | C1: Yes | D1: 01 Anchor | E1: A
A2: Broken | B2: Noticeable | C2: No | D2: 02 Build | E2: B
A3: Barely | B3: Loud | C3: Red Session | D3: 03 Claim | E3: C
E4: Upper A
E5: Lower A
E6: Upper B
E7: Lower B
E8: Test

Sheet Daily Check-In
A1: DAILY CHECK-IN
A2: Sixty seconds every morning. The Status column picks your session — see page 7 of the program.
A4: Start date | B4: =TODAY() | C4: ← type your day 1 here
A6: Date | B6: Sober day | C6: Sleep | D6: Craving | E6: Status | F6: Session done | G6: Notes
A7: =$B$4+0 | B7: =A7-$B$4+1 | E7: =IF(OR(C7="",D7=""),"",IF(OR(C7="Barely",D7="Loud"),"RED",IF(OR(C7="Broken",D7="Noticeable"),"AMBER","GREEN")))
A8: =$B$4+1 | B8: =A8-$B$4+1 | E8: =IF(OR(C8="",D8=""),"",IF(OR(C8="Barely",D8="Loud"),"RED",IF(OR(C8="Broken",D8="Noticeable"),"AMBER","GREEN")))
A9: =$B$4+2 | B9: =A9-$B$4+1 | E9: =IF(OR(C9="",D9=""),"",IF(OR(C9="Barely",D9="Loud"),"RED",IF(OR(C9="Broken",D9="Noticeable"),"AMBER","GREEN")))
A10: =$B$4+3 | B10: =A10-$B$4+1 | E10: =IF(OR(C10="",D10=""),"",IF(OR(C10="Barely",D10="Loud"),"RED",IF(OR(C10="Broken",D10="Noticeable"),"AMBER","GREEN")))
A11: =$B$4+4 | B11: =A11-$B$4+1 | E11: =IF(OR(C11="",D11=""),"",IF(OR(C11="Barely",D11="Loud"),"RED",IF(OR(C11="Broken",D11="Noticeable"),"AMBER","GREEN")))
A12: =$B$4+5 | B12: =A12-$B$4+1 | E12: =IF(OR(C12="",D12=""),"",IF(OR(C12="Barely",D12="Loud"),"RED",IF(OR(C12="Broken",D12="Noticeable"),"AMBER","GREEN")))
A13: =$B$4+6 | B13: =A13-$B$4+1 | E13: =IF(OR(C13="",D13=""),"",IF(OR(C13="Barely",D13="Loud"),"RED",IF(OR(C13="Broken",D13="Noticeable"),"AMBER","GREEN")))
A14: =$B$4+7 | B14: =A14-$B$4+1 | E14: =IF(OR(C14="",D14=""),"",IF(OR(C14="Barely",D14="Loud"),"RED",IF(OR(C14="Broken",D14="Noticeable"),"AMBER","GREEN")))
A15: =$B$4+8 | B15: =A15-$B$4+1 | E15: =IF(OR(C15="",D15=""),"",IF(OR(C15="Barely",D15="Loud"),"RED",IF(OR(C15="Broken",D15="Noticeable"),"AMBER","GREEN")))
A16: =$B$4+9 | B16: =A16-$B$4+1 | E16: =IF(OR(C16="",D16=""),"",IF(OR(C16="Barely",D16="Loud"),"RED",IF(OR(C16="Broken",D16="Noticeable"),"AMBER","GREEN")))
A17: =$B$4+10 | B17: =A17-$B$4+1 | E17: =IF(OR(C17="",D17=""),"",IF(OR(C17="Barely",D17="Loud"),"RED",IF(OR(C17="Broken",D17="Noticeable"),"AMBER","GREEN")))
A18: =$B$4+11 | B18: =A18-$B$4+1 | E18: =IF(OR(C18="",D18=""),"",IF(OR(C18="Barely",D18="Loud"),"RED",IF(OR(C18="Broken",D18="Noticeable"),"AMBER","GREEN")))
A19: =$B$4+12 | B19: =A19-$B$4+1 | E19: =IF(OR(C19="",D19=""),"",IF(OR(C19="Barely",D19="Loud"),"RED",IF(OR(C19="Broken",D19="Noticeable"),"AMBER","GREEN")))
A20: =$B$4+13 | B20: =A20-$B$4+1 | E20: =IF(OR(C20="",D20=""),"",IF(OR(C20="Barely",D20="Loud"),"RED",IF(OR(C20="Broken",D20="Noticeable"),"AMBER","GREEN")))
A21: =$B$4+14 | B21: =A21-$B$4+1 | E21: =IF(OR(C21="",D21=""),"",IF(OR(C21="Barely",D21="Loud"),"RED",IF(OR(C21="Broken",D21="Noticeable"),"AMBER","GREEN")))
A22: =$B$4+15 | B22: =A22-$B$4+1 | E22: =IF(OR(C22="",D22=""),"",IF(OR(C22="Barely",D22="Loud"),"RED",IF(OR(C22="Broken",D22="Noticeable"),"AMBER","GREEN")))
A23: =$B$4+16 | B23: =A23-$B$4+1 | E23: =IF(OR(C23="",D23=""),"",IF(OR(C23="Barely",D23="Loud"),"RED",IF(OR(C23="Broken",D23="Noticeable"),"AMBER","GREEN")))
A24: =$B$4+17 | B24: =A24-$B$4+1 | E24: =IF(OR(C24="",D24=""),"",IF(OR(C24="Barely",D24="Loud"),"RED",IF(OR(C24="Broken",D24="Noticeable"),"AMBER","GREEN")))
A25: =$B$4+18 | B25: =A25-$B$4+1 | E25: =IF(OR(C25="",D25=""),"",IF(OR(C25="Barely",D25="Loud"),"RED",IF(OR(C25="Broken",D25="Noticeable"),"AMBER","GREEN")))
A26: =$B$4+19 | B26: =A26-$B$4+1 | E26: =IF(OR(C26="",D26=""),"",IF(OR(C26="Barely",D26="Loud"),"RED",IF(OR(C26="Broken",D26="Noticeable"),"AMBER","GREEN")))
A27: =$B$4+20 | B27: =A27-$B$4+1 | E27: =IF(OR(C27="",D27=""),"",IF(OR(C27="Barely",D27="Loud"),"RED",IF(OR(C27="Broken",D27="Noticeable"),"AMBER","GREEN")))
A28: =$B$4+21 | B28: =A28-$B$4+1 | E28: =IF(OR(C28="",D28=""),"",IF(OR(C28="Barely",D28="Loud"),"RED",IF(OR(C28="Broken",D28="Noticeable"),"AMBER","GREEN")))
A29: =$B$4+22 | B29: =A29-$B$4+1 | E29: =IF(OR(C29="",D29=""),"",IF(OR(C29="Barely",D29="Loud"),"RED",IF(OR(C29="Broken",D29="Noticeable"),"AMBER","GREEN")))
A30: =$B$4+23 | B30: =A30-$B$4+1 | E30: =IF(OR(C30="",D30=""),"",IF(OR(C30="Barely",D30="Loud"),"RED",IF(OR(C30="Broken",D30="Noticeable"),"AMBER","GREEN")))
A31: =$B$4+24 | B31: =A31-$B$4+1 | E31: =IF(OR(C31="",D31=""),"",IF(OR(C31="Barely",D31="Loud"),"RED",IF(OR(C31="Broken",D31="Noticeable"),"AMBER","GREEN")))
A32: =$B$4+25 | B32: =A32-$B$4+1 | E32: =IF(OR(C32="",D32=""),"",IF(OR(C32="Barely",D32="Loud"),"RED",IF(OR(C32="Broken",D32="Noticeable"),"AMBER","GREEN")))
A33: =$B$4+26 | B33: =A33-$B$4+1 | E33: =IF(OR(C33="",D33=""),"",IF(OR(C33="Barely",D33="Loud"),"RED",IF(OR(C33="Broken",D33="Noticeable"),"AMBER","GREEN")))
A34: =$B$4+27 | B34: =A34-$B$4+1 | E34: =IF(OR(C34="",D34=""),"",IF(OR(C34="Barely",D34="Loud"),"RED",IF(OR(C34="Broken",D34="Noticeable"),"AMBER","GREEN")))
A35: =$B$4+28 | B35: =A35-$B$4+1 | E35: =IF(OR(C35="",D35=""),"",IF(OR(C35="Barely",D35="Loud"),"RED",IF(OR(C35="Broken",D35="Noticeable"),"AMBER","GREEN")))
A36: =$B$4+29 | B36: =A36-$B$4+1 | E36: =IF(OR(C36="",D36=""),"",IF(OR(C36="Barely",D36="Loud"),"RED",IF(OR(C36="Broken",D36="Noticeable"),"AMBER","GREEN")))
A37: =$B$4+30 | B37: =A37-$B$4+1 | E37: =IF(OR(C37="",D37=""),"",IF(OR(C37="Barely",D37="Loud"),"RED",IF(OR(C37="Broken",D37="Noticeable"),"AMBER","GREEN")))
A38: =$B$4+31 | B38: =A38-$B$4+1 | E38: =IF(OR(C38="",D38=""),"",IF(OR(C38="Barely",D38="Loud"),"RED",IF(OR(C38="Broken",D38="Noticeable"),"AMBER","GREEN")))
A39: =$B$4+32 | B39: =A39-$B$4+1 | E39: =IF(OR(C39="",D39=""),"",IF(OR(C39="Barely",D39="Loud"),"RED",IF(OR(C39="Broken",D39="Noticeable"),"AMBER","GREEN")))
A40: =$B$4+33 | B40: =A40-$B$4+1 | E40: =IF(OR(C40="",D40=""),"",IF(OR(C40="Barely",D40="Loud"),"RED",IF(OR(C40="Broken",D40="Noticeable"),"AMBER","GREEN")))
A41: =$B$4+34 | B41: =A41-$B$4+1 | E41: =IF(OR(C41="",D41=""),"",IF(OR(C41="Barely",D41="Loud"),"RED",IF(OR(C41="Broken",D41="Noticeable"),"AMBER","GREEN")))
A42: =$B$4+35 | B42: =A42-$B$4+1 | E42: =IF(OR(C42="",D42=""),"",IF(OR(C42="Barely",D42="Loud"),"RED",IF(OR(C42="Broken",D42="Noticeable"),"AMBER","GREEN")))
...

Sheet Training Log
A1: TRAINING LOG
A2: One row per set, or one row per exercise using your top set. Estimated 1RM calculates itself.
A4: Date | B4: Sober day | C4: Phase | D4: Session | E4: Exercise | F4: Weight | G4: Reps | H4: RPE | I4: Est. 1RM | J4: Notes
B5: =IF(A5="","",A5-'Daily Check-In'!$B$4+1) | I5: =IF(OR(F5="",G5=""),"",ROUND(F5*(1+G5/30),1))
B6: =IF(A6="","",A6-'Daily Check-In'!$B$4+1) | I6: =IF(OR(F6="",G6=""),"",ROUND(F6*(1+G6/30),1))
B7: =IF(A7="","",A7-'Daily Check-In'!$B$4+1) | I7: =IF(OR(F7="",G7=""),"",ROUND(F7*(1+G7/30),1))
B8: =IF(A8="","",A8-'Daily Check-In'!$B$4+1) | I8: =IF(OR(F8="",G8=""),"",ROUND(F8*(1+G8/30),1))
B9: =IF(A9="","",A9-'Daily Check-In'!$B$4+1) | I9: =IF(OR(F9="",G9=""),"",ROUND(F9*(1+G9/30),1))
B10: =IF(A10="","",A10-'Daily Check-In'!$B$4+1) | I10: =IF(OR(F10="",G10=""),"",ROUND(F10*(1+G10/30),1))
B11: =IF(A11="","",A11-'Daily Check-In'!$B$4+1) | I11: =IF(OR(F11="",G11=""),"",ROUND(F11*(1+G11/30),1))
B12: =IF(A12="","",A12-'Daily Check-In'!$B$4+1) | I12: =IF(OR(F12="",G12=""),"",ROUND(F12*(1+G12/30),1))
B13: =IF(A13="","",A13-'Daily Check-In'!$B$4+1) | I13: =IF(OR(F13="",G13=""),"",ROUND(F13*(1+G13/30),1))
B14: =IF(A14="","",A14-'Daily Check-In'!$B$4+1) | I14: =IF(OR(F14="",G14=""),"",ROUND(F14*(1+G14/30),1))
B15: =IF(A15="","",A15-'Daily Check-In'!$B$4+1) | I15: =IF(OR(F15="",G15=""),"",ROUND(F15*(1+G15/30),1))
B16: =IF(A16="","",A16-'Daily Check-In'!$B$4+1) | I16: =IF(OR(F16="",G16=""),"",ROUND(F16*(1+G16/30),1))
... B424: =IF(A424="","",A424-'Daily Check-In'!$B$4+1) | I424: =IF(OR(F424="",G424=""),"",ROUND(F424*(1+G424/30),1))

Sheet Dashboard
B1: DASHBOARD
B2: Everything here calculates itself. Nothing on this tab needs typing.
B4: SOBRIETY | E4: TRAINING
B5: Current sober day | C5: =IFERROR(MAX(0,TODAY()-'Daily Check-In'!$B$4+1),0) | E5: Sessions completed | F5: =COUNTIF('Daily Check-In'!F7:F106,"Yes")
B6: Days checked in | C6: =COUNTIF('Daily Check-In'!E7:E106,"GREEN")+COUNTIF('Daily Check-In'!E7:E106,"AMBER")+COUNTIF('Daily Check-In'!E7:E106,"RED") | E6: Red Sessions completed | F6: =COUNTIF('Daily Check-In'!F7:F106,"Red Session")
B7: Green days | C7: =COUNTIF('Daily Check-In'!E7:E106,"GREEN") | E7: Total sessions (both count) | F7: =COUNTIF('Daily Check-In'!F7:F106,"Yes")+COUNTIF('Daily Check-In'!F7:F106,"Red Session")
B8: Amber days | C8: =COUNTIF('Daily Check-In'!E7:E106,"AMBER") | E8: Sets logged | F8: =COUNT('Training Log'!F5:F424)
B9: Red days | C9: =COUNTIF('Daily Check-In'!E7:E106,"RED") | E9: Total volume (weight x reps) | F9: =IFERROR(SUMPRODUCT('Training Log'!F5:F424,'Training Log'!G5:G424),0)
B10: Green day rate | C10: =IFERROR(COUNTIF('Daily Check-In'!E7:E106,"GREEN")/(COUNTIF('Daily Check-In'!E7:E106,"GREEN")+COUNTIF('Daily Check-In'!E7:E106,"AMBER")+COUNTIF('Daily Check-In'!E7:E106,"RED")),0) | E10: Program adherence (of 44) | F10: =IFERROR((COUNTIF('Daily Check-In'!F7:F106,"Yes")+COUNTIF('Daily Check-In'!F7:F106,"Red Session"))/44,0)
B12: BEST ESTIMATED 1RM | E12: Matches any exercise name containing the keyword.
B13: Squat | C13: =IFERROR(MAX(IF(ISNUMBER(SEARCH("squat",'Training Log'!$E$5:$E$424)),'Training Log'!$I$5:$I$424)),0)
B14: Bench | C14: =IFERROR(MAX(IF(ISNUMBER(SEARCH("bench",'Training Log'!$E$5:$E$424)),'Training Log'!$I$5:$I$424)),0)
B15: Deadlift | C15: =IFERROR(MAX(IF(ISNUMBER(SEARCH("deadlift",'Training Log'!$E$5:$E$424)),'Training Log'!$I$5:$I$424)),0)
B16: Overhead Press | C16: =IFERROR(MAX(IF(ISNUMBER(SEARCH("overhead",'Training Log'!$E$5:$E$424)),'Training Log'!$I$5:$I$424)),0)
B17: Row | C17: =IFERROR(MAX(IF(ISNUMBER(SEARCH("row",'Training Log'!$E$5:$E$424)),'Training Log'!$I$5:$I$424)),0)
B18: Pull-Up / Pulldown | C18: =IFERROR(MAX(IF(ISNUMBER(SEARCH("pull",'Training Log'!$E$5:$E$424)),'Training Log'!$I$5:$I$424)),0)
B20: These six are array formulas. In Excel 2019 or older, click the cell, press F2 then Ctrl+Shift+Enter. Excel 365, Google Sheets, Numbers and LibreOffice need no extra step.
B22: Not medical advice. Alcohol withdrawal can be dangerous — speak to a doctor. SAMHSA National Helpline (US): 1-800-662-4357.
